Workbook
Name \P: #REF!
Name \P: #REF!
Name \PP: #REF!
Name \Q: #REF!
Name ___pg1: #REF!
Name ___pg1: #REF!
Name ___pg1: #REF!
Name ___pg1: #REF!
Name ___pg1: #REF!
Name __DTL1: #REF!
Name __DTL1: #REF!
Name __DTL1: #REF!
Name __DTL1: #REF!
Name __DTL1: #REF!
Name __pg1: #REF!
Name __pg1: #REF!
Name __pg1: #REF!
Name __pg1: #REF!
Name __pg1: #REF!
Name _DTL1: #REF!
Name _DTL1: #REF!
Name _DTL1: #REF!
Name _DTL1: #REF!
Name _DTL1: #REF!
Name _pg1: #REF!
Name _pg1: #REF!
Name _pg1: #REF!
Name _pg1: #REF!
Name _pg1: #REF!
Name _Q: #REF!
Name ASRFY: Input!$F$49
Name BExGrid1: #REF!
Name BExItemGrid: #REF!
Name bs: #REF!
Name bs: #REF!
Name bs: #REF!
Name bs: #REF!
Name bs: #REF!
Name bss: #REF!
Name bss: #REF!
Name bss: #REF!
Name bss: #REF!
Name bss: #REF!
Name BU: [1]Drop_Downs!$A$5:$A$22
Name BudgetOwner: #REF!
Name BudgetOwner: #REF!
Name BudgetOwner: #REF!
Name BUTable: [1]Drop_Downs!$A$37:$B$50
Name CASHFLOWS: #REF!
Name Cat: [1]Drop_Downs!$O$32:$O$39
Name Comp: Input!$D$51
Name COMPARISON: #REF!
Name COMPARISON: #REF!
Name CurrentFY: Input!$F$48
Name CurrentFYPriorSub: Current_Prior!$BQ$33
Name DefExitFY: Input!$N$59
Name DefExitFYOrig: HistInfo!$AB$44
Name DEMAND: #REF!
Name DEMAND: #REF!
Name DEMAND: #REF!

Sheet Inst
B2: Instructions
B4: Steps to incorporate Financial Template to your current R&D Business Cases
C5: 1 | H5: Create and Move a copy of all green tabs from this file ("Inst", "Input", "Calc", "Current_Prior", "HistInfo" "PPT" and "PPD_DD") to your current business case (BC) models.
C6: =C5+1 -> 2 | H6: Populate and Link information at "Input", "Calc", "Current_Prior" and "HistInfo". "PPT" tab is a summary of recommended information to be used in R&D BC discussions.
C7: =C6+1 -> 3 | H7: Save new BC package (BC model + Financial Template) at R&D BC Sharepoint. Access is segregated by BU folder. Keep a "live" file, which should be updated any time that project has a significant change, exits any GPDS phase, goes through ASR and budget review cycles. However, before updating BC at Sharepoint, make sure that you create a copy of previous version and save it at Repositorium/Historical folder (it is important to keep previous BC versions to assuring continuity and to avoid information loss, mainly when associates rotate to new positions).
B9: Tab: Basic Input (Input)
C10: # | D10: Columns | F10: Rows
C11: 1 | D11: =HLOOKUP(COLUMN(Input!A2),FT_PPD_DD!$A$116:$DZ$117,2,0) -> A | E11: =HLOOKUP(COLUMN(Input!R2),FT_PPD_DD!$A$116:$DZ$117,2,0) -> R | F11: =ROW(Input!A2) -> 2 | G11: =ROW(Input!R112) -> 112 | H11: Required Input: fileds in this session will load formulas on following tabs
C12: =C11+1 -> 2 | F12: =ROW(Input!D4) -> 4 | H12: Segment: Input Segment name
C13: =C12+1 -> 3 | F13: =ROW(Input!D5) -> 5 | H13: Business Unit: Input BU name
C14: =C13+1 -> 4 | F14: =ROW(Input!D7) -> 7 | H14: Update Date: Input last update date (calendar year)
C15: =C14+1 -> 5 | F15: =ROW(Input!D8) -> 8 | H15: PDT (Portfolio Decision Team): Input date of last PDT (calendar year)
C16: =C15+1 -> 6 | F16: =ROW(Input!D10) -> 10 | H16: Business Case (BC) Name: Input Business Case Name
C17: =C16+1 -> 7 | F17: =ROW(Input!D11) -> 11 | H17: Business Case Identification (BCID): Input Business Case ID number
C18: =C17+1 -> 8 | F18: =ROW(Input!D12) -> 12 | H18: 15 Yr Business Case?: Using drop down list, select whether project is a 10 or 15 yr time horizon. NOTE: standard guide is to projects be under 10 yr time horizon - 15 yr projects should be approved on an exception base
C19: =C17+1 -> 8 | F19: =ROW(Input!D15) -> 15 | H19: BPC Number: Input BPC project number and names associated to business case. It might be the case that multiple BPC projects refer to a single business case (BC)
C20: =C19+1 -> 9 | F20: =ROW(Input!D32) -> 32 | G20: =ROW(Input!D36) -> 36 | H20: Input product name. If business case is compounded by multiple products, list product names on following columns, starting on column D with most representative product in sales
C21: =C20+1 -> 10 | F21: =ROW(Input!D47) -> 47 | H21: Project Start FY: Input project start fiscal year
C22: =C21+1 -> 11 | F22: =ROW(Input!D48) -> 48 | H22: Current FY: Input current fiscal year
C23: =C22+1 -> 12 | F23: =ROW(Input!D49) -> 49 | H23: ASR FY: Input first year of ASR period
C24: =C23+1 -> 13 | F24: =ROW(Input!D51) -> 51 | H24: Comparison Scenario: Use drop down list to select compariosn bases. The default comparison base is the Def Exit scenario, but there are cases that a new rebaseline was approved and set as comparison scenario
C25: =C24+1 -> 14 | F25: =ROW(Input!D52) -> 52 | H25: If Rebaseline, input switch date: provide date of rebaseline, if a new scenario other than the Def Exit is been used
C26: =C25+1 -> 15 | F26: =ROW(Input!D55) -> 55 | H26: Current GPDS Phase: Input current GPDS phase (Concept, Definition, Development, Qualification, Launch). If project has multiple phase, input phase related to the most relevant product
C27: =C26+1 -> 16 | F27: =ROW(Input!D57) -> 57 | H27: Project Start: Input month and year of project start (calendar year)
C28: =C27+1 -> 17 | D28: =HLOOKUP(COLUMN(Input!D58),FT_PPD_DD!$A$116:$DZ$117,2,0) -> D | E28: =HLOOKUP(COLUMN(Input!H63),FT_PPD_DD!$A$116:$DZ$117,2,0) -> H | F28: =ROW(Input!D58) -> 58 | G28: =ROW(Input!E63) -> 63 | H28: Date of Exit GPDS Phase (Mth/Year): for each GPDS phase listed (Concept, Definition, Development, Qualification, Launch), input month and year (calendar year) of exiting. Use Commitment column to input dates expected to project exit each phase by the time that Project Exited Definition phase. Use "Current" column to input actual and/or most updated dates. Definition and Launch Current and Exit fileds will be used to adjust formulas at "Calculation" and "Presentation" tabs
C29: =C28+1 -> 18 | F29: =ROW(Input!D66) -> 66 | H29: Tax Rate: Input tax rate used for modeling
C30: =C29+1 -> 19 | F30: =ROW(Input!D67) -> 67 | H30: Tax Rate: Input tax rate used in Definition Exit or Rebaseline scenario. If there is no distinction, please input same number on both fields
C31: =C30+1 -> 20 | F31: =ROW(Input!D68) -> 68 | H31: Discount Rate: Input discount rate used for modeling. Discount rate will also be considered as project hurdle rate
C32: =C31+1 -> 21 | F32: =ROW(Input!D69) -> 69 | H32: Discount Rate @ Def Exit: If project had a different discount rate by the time that it exited Definition GPDS phase, insert its rate at this row
C33: =C32+1 -> 22 | F33: =ROW(Input!D70) -> 70 | H33: Commercial Risk: Input Commercail risk of project; use drop down list (low, medium, high)
C34: =C33+1 -> 23 | F34: =ROW(Input!D71) -> 71 | H34: Technical Risk: Input Technical risk of project; use drop down list (low, medium, high)
C35: =C34+1 -> 24 | F35: =ROW(Input!D72) -> 72 | H35: Finance Rate (for MIRR calc): Input finance rate (used to calculate MIRR); this is the cost of capital that is funding the project. BD WACC is a resonable rate, if project is funded internally (no debt is required to fund it). Please, double check most updated BD WACC rate (we are currently using 8%)
C36: =C35+1 -> 25 | F36: =ROW(Input!D73) -> 73 | H36: Reinvestment Rate (for MIRR calc): Input reinvestment rate (used to calculate MIRR); it represents the rate at which project cash flow is reinvested. Per capital recommendation, rate should be 12.5%
C37: =C36+1 -> 26 | F37: =ROW(Input!D74) -> 74 | H37: Growth Rate (for Terminal Value calc): Input growth rate used for modeling terminal value, if applicable
C38: =C37+1 -> 27 | F38: =ROW(Input!D76) -> 76 | G38: =ROW(Input!E78) -> 78 | H38: Number of Days (for Working Capital calculation): Input number of days to be considered in each of those 3 metrics: DSO (Receivables), DPO (Payables), DIO (Inventories). Columns J and K show BDX days related to FY16 actual figures. If needed, as reference, "PPD_DD" tab, rows 101 to 113 show a more detailed breakdown by BU (for DIO) and by region (for DSO and DPO) as FY16 actuals. Figures provide by Treasury.
C39: =C38+1 -> 28 | D39: =HLOOKUP(COLUMN(Input!B81),FT_PPD_DD!$A$116:$DZ$117,2,0) -> B | F39: =ROW(Input!D81) -> 81 | H39: SMS Name: Input SMS (Strategic Market Space) name, using drop down list. Based on the SMS name, table will automatically load remaining information. If you have a new SMS, override formula and fill information accordingly
C40: =C39+1 -> 29 | F40: =ROW(Input!D82) -> 82 | H40: Quadrant: Populated automatically; Input SMS quadrant, if formula does not work
C41: =C40+1 -> 30 | F41: =ROW(Input!D83) -> 83 | H41: SMS FY17 Rev ($ M): Populated automatically; Input revenues related to SMS as FY current year or most updated revenue expectation on SMS category, if formula does not work
C42: =C41+1 -> 31 | F42: =ROW(Input!D84) -> 84 | H42: FY17 Share: Populated automatically; Input share defined by SMS FY 15 Revenues divided by Size Addressable FY 17 WW Mkt ($ M), if formula does not work
C43: =C42+1 -> 32 | F43: =ROW(Input!D85) -> 85 | H43: Size Addressable FY 17 WW Mkt ($ M): Populated automatically; Input size in dollar amount of addressabale worldwide SMS market as FY17, if formula does not work
...

Sheet Input
B2: Required Inputs (feed template fornulas) | U2: Additional Inputs (provide extra contextect to project - not linked to formulas)
B4: Segment | D4: Life Sciences
B5: Business Unit | D5: BDB
B7: Latest Update on (calendar year): | D7: N/A | E7: N/A | F7: N/A
B8: Latest Portfolio Decision Team - PDT on (calendar year): | D8: N/A | E8: N/A | F8: N/A
B10: Business Case Name
B11: Business Case Identification (BCID)
B12: 15 Yr Business Case? (Y/N) | D12: Yes (exception)
B14: BPC Projects Associated to Business Case: | D14: Code | J14: Name
B31: New Product (NP) Revenue Build Up | D31: Name
B32: NP - Main | D32: A
B33: NP 2 | D33: B
B34: NP 3 | D34: C
B35: NP 4 | D35: D
B36: NP 5 | D36: E
B38: Project Description
B39: <<Please provide a brief and high level project / product description; no need to be a technical explanation>>
B46: Dates and Terms - Fiscal Year Input
B47: Project Start FY | D47: FY18 | F47: =RIGHT(D47,2)*1 -> 18
B48: Current FY | D48: FY18 | F48: =RIGHT(D48,2)*1 -> 18
B49: ASR FY (start yr) | D49: N/A | F49: =RIGHT(D49,2)*1 -> #VALUE!
B51: Comparison Scenario | D51: Def Exit | U51: Information provided in this session is not physically linked to template formulas (further tabs or left side of this tab). However, you may prefer to link them, if applicable to your model.
B52: If Rebaseline, input switch date (Calendar Year) | D52: N/A | E52: N/A | U52: Dates of Exit GPDS Phase: Month / Calendar Year
B54: GPDS Phase and Terms | U54: Product or Region | V54: <Name> | AA54: <Name> | AF54: <Name> | AK54: <Name> | AP54: <Name>
B55: Current GPDS Phase | D55: N/A | J55: Fiscal Year Equivalent | U55: Current GPDS Phase | V55: N/A | AA55: N/A | AF55: N/A | AK55: N/A | AP55: N/A
B56: Dates of Exit GPDS Phase: Month / Calendar Year | D56: Current | F56: Commitment | J56: Current | L56: Commit | U56: Month / Calendar Year | V56: Current | X56: Commitment | AA56: Current | AC56: Commitment | AF56: Current | AH56: Commitment | AK56: Current | AM56: Commitment | AP56: Current | AR56: Commitment
B57: Project Start | D57: N/A | E57: N/A | F57: N/A | G57: 16 | H57: N/A | J57: ="FY"&IF(OR(D57="Oct",D57="Nov",D57="Dec"),E57+1,E57) -> FYN/A | L57: ="FY"&IF(OR(F57="Oct",F57="Nov",F57="Dec"),H57+1,H57) -> FYN/A
B58: Concept | D58: N/A | E58: N/A | F58: N/A | G58: 16 | H58: N/A | J58: ="FY"&IF(OR(D58="Oct",D58="Nov",D58="Dec"),E58+1,E58) -> FYN/A | L58: ="FY"&IF(OR(F58="Oct",F58="Nov",F58="Dec"),H58+1,H58) -> FYN/A | U58: Concept | V58: N/A | W58: N/A | X58: N/A | Y58: N/A | AA58: N/A | AB58: N/A | AC58: N/A | AD58: N/A | AF58: N/A | AG58: N/A | AH58: N/A | AI58: N/A | AK58: N/A | AL58: N/A | AM58: N/A | AN58: N/A | AP58: N/A | AQ58: N/A | AR58: N/A | AS58: N/A
B59: Definition | D59: N/A | E59: N/A | F59: N/A | G59: 16 | H59: N/A | J59: ="FY"&IF(OR(D59="Oct",D59="Nov",D59="Dec"),E59+1,E59) -> FYN/A | L59: ="FY"&IF(OR(F59="Oct",F59="Nov",F59="Dec"),H59+1,H59) -> FYN/A | N59: =RIGHT(J59,2)*1 -> #VALUE! | U59: Definition | V59: N/A | W59: N/A | X59: N/A | Y59: N/A | AA59: N/A | AB59: N/A | AC59: N/A | AD59: N/A | AF59: N/A | AG59: N/A | AH59: N/A | AI59: N/A | AK59: N/A | AL59: N/A | AM59: N/A | AN59: N/A | AP59: N/A | AQ59: N/A | AR59: N/A | AS59: N/A
D60: Current | F60: =Comp&" Commit" -> Def Exit Commit | V60: Current | X60: =Comp&" Commit" -> Def Exit Commit | AA60: Current | AC60: =Comp&" Commit" -> Def Exit Commit | AF60: Current | AH60: =Comp&" Commit" -> Def Exit Commit | AK60: Current | AM60: =Comp&" Commit" -> Def Exit Commit | AP60: Current | AR60: =Comp&" Commit" -> Def Exit Commit
B61: Development | D61: N/A | E61: N/A | F61: N/A | G61: 16 | H61: N/A | J61: ="FY"&IF(OR(D61="Oct",D61="Nov",D61="Dec"),E61+1,E61) -> FYN/A | L61: ="FY"&IF(OR(F61="Oct",F61="Nov",F61="Dec"),H61+1,H61) -> FYN/A | U61: Development | V61: N/A | W61: N/A | X61: N/A | Y61: N/A | AA61: N/A | AB61: N/A | AC61: N/A | AD61: N/A | AF61: N/A | AG61: N/A | AH61: N/A | AI61: N/A | AK61: N/A | AL61: N/A | AM61: N/A | AN61: N/A | AP61: N/A | AQ61: N/A | AR61: N/A | AS61: N/A
B62: Qualification | D62: N/A | E62: N/A | F62: N/A | G62: 16 | H62: N/A | J62: ="FY"&IF(OR(D62="Oct",D62="Nov",D62="Dec"),E62+1,E62) -> FYN/A | L62: ="FY"&IF(OR(F62="Oct",F62="Nov",F62="Dec"),H62+1,H62) -> FYN/A | U62: Qualification | V62: N/A | W62: N/A | X62: N/A | Y62: N/A | AA62: N/A | AB62: N/A | AC62: N/A | AD62: N/A | AF62: N/A | AG62: N/A | AH62: N/A | AI62: N/A | AK62: N/A | AL62: N/A | AM62: N/A | AN62: N/A | AP62: N/A | AQ62: N/A | AR62: N/A | AS62: N/A
B63: Launch | D63: N/A | E63: N/A | F63: N/A | H63: N/A | J63: ="FY"&IF(OR(D63="Oct",D63="Nov",D63="Dec"),E63+1,E63) -> FYN/A | L63: ="FY"&IF(OR(F63="Oct",F63="Nov",F63="Dec"),H63+1,H63) -> FYN/A | N63: =RIGHT(J63,2)*1 -> #VALUE! | O63: =RIGHT(L63,2)*1 -> #VALUE! | U63: Launch | V63: N/A | W63: N/A | X63: N/A | Y63: N/A | AA63: N/A | AB63: N/A | AC63: N/A | AD63: N/A | AF63: N/A | AG63: N/A | AH63: N/A | AI63: N/A | AK63: N/A | AL63: N/A | AM63: N/A | AN63: N/A | AP63: N/A | AQ63: N/A | AR63: N/A | AS63: N/A
U64: ="Revenue Rep (DefExit 10 or 15yrs)" -> Revenue Rep (DefExit 10 or 15yrs) | X64: 0 | AC64: 0 | AH64: 0 | AM64: 0 | AR64: 0
B65: Financial Inputs
B66: Tax Rate @ Act/Projection Scenarios | D66: 0.28 | F66: =D66 -> 0.28
B67: ="Tax Rate @ "&Comp&" Scenario (if different)" -> Tax Rate @ Def Exit Scenario (if different) | D67: =D66 -> 0.28 | F67: =D67 -> 0.28
B68: Discount (Hurdle) Rate @ Act/Projection Scenarios | D68: 0.15 | F68: =D68 -> 0.15 | G68: =F68*100 -> 15 | U68: Regional Launches
B69: ="Disc (Hurdle) Rate @ "&Comp&" Scenario (if different)" -> Disc (Hurdle) Rate @ Def Exit Scenario (if different) | D69: =D68 -> 0.15 | F69: =D69 -> 0.15 | V69: Expected Launch at
B70: Commercial Risk | D70: N/A | V70: Actual | X70: =Comp&" Commit" -> Def Exit Commit
...

Sheet Current_Prior
B2: Current vs. Prios Submission Comparison
B4: Please, paste values refereing to Prior Submission on light green highlighted cells (AP14 to BW 47)
B6: Current Submission | AP6: Prior Submission
AJ8: 10 Yrs | AM8: 15 Yrs
F9: Sunk | G9: =Calc!G125 -> FY18 | H9: =Calc!H125 -> FY19 | I9: =Calc!I125 -> FY20 | J9: =Calc!J125 -> FY21 | K9: =Calc!K125 -> FY22 | L9: =Calc!L125 -> FY23 | M9: =Calc!M125 -> FY24 | N9: =Calc!N125 -> FY25 | ... AI9: =Calc!AI125 -> FY46 | AJ9: =Calc!AJ9 -> FY18-27 | AK9: % Rev | AM9: =Calc!AM9 -> FY18-32 | AP9: Sunk | AQ9: =G9 -> FY18 | AR9: =H9 -> FY19 | AS9: =I9 -> FY20 | AT9: =J9 -> FY21 | AU9: =K9 -> FY22 | AV9: =L9 -> FY23 | AW9: =M9 -> FY24 | AX9: =N9 -> FY25 | ... BS9: =AI9 -> FY46 | BT9: FYAA-FYBB | BU9: % Rev | BW9: FYAA-FYBB
B11: Incremental Revenue | F11: =Calc!F127 -> 0 | G11: =Calc!G127 -> 0 | H11: =Calc!H127 -> 0 | I11: =Calc!I127 -> 0 | J11: =Calc!J127 -> 0 | K11: =Calc!K127 -> 0 | L11: =Calc!L127 -> 16667.204 | M11: =Calc!M127 -> 38568.729 | ... AJ11: =Calc!AJ127 -> 376419.95 | AM11: =Calc!AM127 -> 1323354.4
B12: Growth % | G12: =Calc!G128 -> 0 | H12: =Calc!H128 -> 0 | I12: =Calc!I128 -> 0 | J12: =Calc!J128 -> 0 | K12: =Calc!K128 -> 0 | L12: =Calc!L128 -> 0 | M12: =Calc!M128 -> 1.3140492 | N12: =Calc!N128 -> 0.90631038 | ... AJ12: =Calc!AJ128 -> 0.69427697 | AK12: 5 Yr CAGR
B13: Category Share | C13: =Calc!C129 -> Dollar ($) | G13: =Calc!G129 -> 0 | H13: =Calc!H129 -> 0 | I13: =Calc!I129 -> 0 | J13: =Calc!J129 -> 0 | K13: =Calc!K129 -> 0 | L13: =Calc!L129 -> 0 | M13: =Calc!M129 -> 0 | N13: =Calc!N129 -> 0 | ... AJ13: =Calc!AJ129 -> 0
B14: True Inc Rev (exc. Loss Avoid): PPD | G14: =Calc!G130 -> 0 | H14: =Calc!H130 -> 0 | I14: =Calc!I130 -> 0 | J14: =Calc!J130 -> 0 | K14: =Calc!K130 -> 0 | L14: =Calc!L130 -> 16667.204 | M14: =Calc!M130 -> 38568.729 | N14: =Calc!N130 -> 73523.969 | ... AJ14: =Calc!AJ130 -> 376419.95 | AM14: =Calc!AM130 -> 1323354.4
B15: Cost of Sales | F15: =Calc!F131 -> 0 | G15: =Calc!G131 -> 0 | H15: =Calc!H131 -> 0 | I15: =Calc!I131 -> 0 | J15: =Calc!J131 -> 0 | K15: =Calc!K131 -> 0 | L15: =Calc!L131 -> 4910.0681 | M15: =Calc!M131 -> 11698.893 | ... AK15: =Calc!AK131 -> 0.30506292 | AM15: =Calc!AM131 -> 413753.52
B16: Depreciation | F16: =Calc!F132 -> 0 | G16: =Calc!G132 -> 0 | H16: =Calc!H132 -> 0 | I16: =Calc!I132 -> 0 | J16: =Calc!J132 -> 0 | K16: =Calc!K132 -> 0 | L16: =Calc!L132 -> 0 | M16: =Calc!M132 -> 0 | ... AK16: =Calc!AK132 -> 0 | AM16: =Calc!AM132 -> 0
B17: Gross Profit | F17: =+F11-F15-F16 -> 0 | G17: =+G11-G15-G16 -> 0 | H17: =+H11-H15-H16 -> 0 | I17: =+I11-I15-I16 -> 0 | J17: =+J11-J15-J16 -> 0 | K17: =+K11-K15-K16 -> 0 | L17: =+L11-L15-L16 -> 11757.136 | M17: =+M11-M15-M16 -> 26869.837 | ... AI17: =+AI11-AI15-AI16 -> 0 | AJ17: =Calc!AJ133 -> 261588.18 | AM17: =Calc!AM133 -> 909600.9
C18: % of Revenue | G18: =IFERROR(IF(ABS(G17/G$11)>100%,0,G17/G$11),0) -> 0 | H18: =IFERROR(IF(ABS(H17/H$11)>100%,0,H17/H$11),0) -> 0 | I18: =IFERROR(IF(ABS(I17/I$11)>100%,0,I17/I$11),0) -> 0 | J18: =IFERROR(IF(ABS(J17/J$11)>100%,0,J17/J$11),0) -> 0 | K18: =IFERROR(IF(ABS(K17/K$11)>100%,0,K17/K$11),0) -> 0 | L18: =IFERROR(IF(ABS(L17/L$11)>100%,0,L17/L$11),0) -> 0.70540541 | M18: =IFERROR(IF(ABS(M17/M$11)>100%,0,M17/M$11),0) -> 0.69667415 | N18: =IFERROR(IF(ABS(N17/N$11)>100%,0,N17/N$11),0) -> 0.69576747 | ... AJ18: =IFERROR(IF(ABS(AJ17/AJ$11)>100%,0,AJ17/AJ$11),0) -> 0.69493708
B19: SSG&A | F19: =Calc!F135 -> 0 | G19: =Calc!G135 -> 200 | H19: =Calc!H135 -> 1000 | I19: =Calc!I135 -> 2500 | J19: =Calc!J135 -> 3500 | K19: =Calc!K135 -> 4500 | L19: =Calc!L135 -> 3300.0097 | M19: =Calc!M135 -> 3694.2371 | ... AK19: =Calc!AK135 -> 0.078304986 | AM19: =Calc!AM135 -> 52020.379
B20: R&D | F20: =Calc!F136 -> 0 | G20: =Calc!G136 -> 4828.4207 | H20: =Calc!H136 -> 3450.6323 | I20: =Calc!I136 -> 8338.5411 | J20: =Calc!J136 -> 7736.0277 | K20: =Calc!K136 -> 2362.6099 | L20: =Calc!L136 -> 1451.8026 | M20: =Calc!M136 -> 205.83869 | ... AK20: =Calc!AK136 -> 0.077085236 | AM20: =Calc!AM136 -> 29239.227
B21: OIBT | F21: =+F17-F19-F20 -> 0 | G21: =+G17-G19-G20 -> -5028.4207 | H21: =+H17-H19-H20 -> -4450.6323 | I21: =+I17-I19-I20 -> -10838.541 | J21: =+J17-J19-J20 -> -11236.028 | K21: =+K17-K19-K20 -> -6862.6099 | L21: =+L17-L19-L20 -> 7005.3234 | M21: =+M17-M19-M20 -> 22969.761 | ... AI21: =+AI17-AI19-AI20 -> 0 | AJ21: =Calc!AJ137 -> 203096.2 | AM21: =Calc!AM137 -> 828341.29
C22: % of Revenue | F22: =IFERROR(IF(ABS(F21/F$11)>100%,0,F21/F$11),0) -> 0 | G22: =IFERROR(IF(ABS(G21/G$11)>100%,0,G21/G$11),0) -> 0 | H22: =IFERROR(IF(ABS(H21/H$11)>100%,0,H21/H$11),0) -> 0 | I22: =IFERROR(IF(ABS(I21/I$11)>100%,0,I21/I$11),0) -> 0 | J22: =IFERROR(IF(ABS(J21/J$11)>100%,0,J21/J$11),0) -> 0 | K22: =IFERROR(IF(ABS(K21/K$11)>100%,0,K21/K$11),0) -> 0 | L22: =IFERROR(IF(ABS(L21/L$11)>100%,0,L21/L$11),0) -> 0.42030586 | M22: =IFERROR(IF(ABS(M21/M$11)>100%,0,M21/M$11),0) -> 0.595554 | ... AJ22: =IFERROR(IF(ABS(AJ21/AJ$11)>100%,0,AJ21/AJ$11),0) -> 0.53954685
B23: Other (Inc) / Exp | F23: =Calc!F139 -> 0 | G23: =Calc!G139 -> 0 | H23: =Calc!H139 -> 0 | I23: =Calc!I139 -> 0 | J23: =Calc!J139 -> 0 | K23: =Calc!K139 -> 0 | L23: =Calc!L139 -> 933.33333 | M23: =Calc!M139 -> 933.33333 | ... AJ23: =Calc!AJ139 -> 4666.6667 | AK23: Tax Rate | AM23: =Calc!AM139 -> 9333.3333
B24: Tax Exp / (Ben) | F24: =Calc!F140 -> 0 | G24: =Calc!G140 -> -1407.9578 | H24: =Calc!H140 -> -1246.1771 | I24: =Calc!I140 -> -3034.7915 | J24: =Calc!J140 -> -3146.0877 | K24: =Calc!K140 -> -1921.5308 | L24: =Calc!L140 -> 1700.1572 | M24: =Calc!M140 -> 6170.1998 | ... AK24: =Calc!AK140 -> 0.27356627 | AM24: =Calc!AM140 -> 229322.23
B25: Net Income | F25: =F21-F23-F24 -> 0 | G25: =G21-G23-G24 -> -3620.4629 | H25: =H21-H23-H24 -> -3204.4553 | I25: =I21-I23-I24 -> -7803.7496 | J25: =J21-J23-J24 -> -8089.9399 | K25: =K21-K23-K24 -> -4941.0791 | L25: =L21-L23-L24 -> 4371.8328 | M25: =M21-M23-M24 -> 15866.228 | ... AI25: =AI21-AI23-AI24 -> 0 | AJ25: =Calc!AJ141 -> 142869.26 | AM25: =Calc!AM141 -> 589685.73
C26: % of Revenue | G26: =IFERROR(IF(ABS(G25/G$11)>100%,0,G25/G$11),0) -> 0 | H26: =IFERROR(IF(ABS(H25/H$11)>100%,0,H25/H$11),0) -> 0 | I26: =IFERROR(IF(ABS(I25/I$11)>100%,0,I25/I$11),0) -> 0 | J26: =IFERROR(IF(ABS(J25/J$11)>100%,0,J25/J$11),0) -> 0 | K26: =IFERROR(IF(ABS(K25/K$11)>100%,0,K25/K$11),0) -> 0 | L26: =IFERROR(IF(ABS(L25/L$11)>100%,0,L25/L$11),0) -> 0.26230152 | M26: =IFERROR(IF(ABS(M25/M$11)>100%,0,M25/M$11),0) -> 0.41137544 | N26: =IFERROR(IF(ABS(N25/N$11)>100%,0,N25/N$11),0) -> 0.45721121 | ... AJ26: =IFERROR(IF(ABS(AJ25/AJ$11)>100%,0,AJ25/AJ$11),0) -> 0.37954753
B27: Capital | F27: =Calc!F143 -> 0 | G27: =Calc!G143 -> 0 | H27: =Calc!H143 -> 0 | I27: =Calc!I143 -> 0 | J27: =Calc!J143 -> 0 | K27: =Calc!K143 -> 0 | L27: =Calc!L143 -> 13066.667 | M27: =Calc!M143 -> -933.33333 | ... AK27: =Calc!AK143 -> 0.024795002 | AM27: =Calc!AM143 -> 4666.6667
B28: Increase in Working Capital | F28: =Calc!F144 -> 0 | G28: =Calc!G144 -> 0 | H28: =Calc!H144 -> 0 | I28: =Calc!I144 -> 0 | J28: =Calc!J144 -> 0 | K28: =Calc!K144 -> 0 | L28: =Calc!L144 -> 3160.1369 | M28: =Calc!M144 -> 4194.6695 | ... AK28: =Calc!AK144 -> 0.069754615 | AM28: =Calc!AM144 -> 45804.169
B29: Free Cash Flow | F29: =F25+F16-F27-F28 -> 0 | G29: =G25+G16-G27-G28 -> -3620.4629 | H29: =H25+H16-H27-H28 -> -3204.4553 | I29: =I25+I16-I27-I28 -> -7803.7496 | J29: =J25+J16-J27-J28 -> -8089.9399 | K29: =K25+K16-K27-K28 -> -4941.0791 | L29: =L25+L16-L27-L28 -> -11854.971 | M29: =M25+M16-M27-M28 -> 12604.892 | ... AI29: =AI25+AI16-AI27-AI28 -> 0 | AJ29: =Calc!AJ145 -> 107278.9 | AM29: =Calc!AM145 -> 539214.89
C30: % of Revenue | G30: =IFERROR(IF(ABS(G29/G$11)>100%,0,G29/G$11),0) -> 0 | H30: =IFERROR(IF(ABS(H29/H$11)>100%,0,H29/H$11),0) -> 0 | I30: =IFERROR(IF(ABS(I29/I$11)>100%,0,I29/I$11),0) -> 0 | J30: =IFERROR(IF(ABS(J29/J$11)>100%,0,J29/J$11),0) -> 0 | K30: =IFERROR(IF(ABS(K29/K$11)>100%,0,K29/K$11),0) -> 0 | L30: =IFERROR(IF(ABS(L29/L$11)>100%,0,L29/L$11),0) -> -0.71127532 | M30: =IFERROR(IF(ABS(M29/M$11)>100%,0,M29/M$11),0) -> 0.32681636 | N30: =IFERROR(IF(ABS(N29/N$11)>100%,0,N29/N$11),0) -> 0.37913141 | ... AJ30: =IFERROR(IF(ABS(AJ29/AJ$11)>100%,0,AJ29/AJ$11),0) -> 0.28499792
B31: ="Discounted FCF to Current FY (FY"&CurrentFY&")*" -> Discounted FCF to Current FY (FY18)* | G31: =Calc!G147 -> -3620.4629 | H31: =Calc!H147 -> -2786.4829 | I31: =Calc!I147 -> -5900.7558 | J31: =Calc!J147 -> -5319.2668 | K31: =Calc!K147 -> -2825.078 | L31: =Calc!L147 -> -5894.0156 | M31: =Calc!M147 -> 5449.4426 | N31: =Calc!N147 -> 10479.338 | ... AJ31: =Calc!AJ147 -> 21754.78 | AM31: =Calc!AM147 -> 101683.22
B32: * No Undepreciated Captital and/or Terminal Value Adjustment
BL33: Current FY (Prior Submission) | BO33: N/A | BP33: Fiscal Year | BQ33: =RIGHT(BO33,2)*1 -> #VALUE!
Q34: 10 Yrs | U34: 15 Yrs | BA34: 10 Yrs | BF34: 15 Yrs | BL34: Disc Rate (Prior Submission)
H35: Business Case Owners (Current) | Q35: =Comp&" Act/Proj" -> Def Exit Act/Proj | R35: Fwd Look | S35: Fwd Look ASR | U35: =Comp&" Act/Proj" -> Def Exit Act/Proj | V35: Fwd Look | W35: Fwd Look ASR | AR35: Business Case Owners (Prior Submission) | BA35: Proj Start | BB35: =Comp&" Commit" -> Def Exit Commit | BC35: =Comp&" Act/Proj" -> Def Exit Act/Proj | BD35: Fwd Look | BE35: Fwd Look ASR | BF35: Proj Start | BG35: =Comp&" Commit" -> Def Exit Commit | BH35: =Comp&" Act/Proj" -> Def Exit Act/Proj | BI35: Fwd Look | BJ35: Fwd Look ASR | BN35: Calendar Year
H36: Name and Last Review Date (Calendar Year) | Q36: ="FY "&DefExitFY&"-"&DefExitFY+9 -> #VALUE! | R36: ="FY "&CurrentFY&"-"&CurrentFY+9 -> FY 18-27 | S36: ="FY "&ASRFY&"-"&ASRFY+9 -> #VALUE! | U36: ="FY "&DefExitFY&"-"&DefExitFY+14 -> #VALUE! | V36: ="FY "&CurrentFY&"-"&CurrentFY+14 -> FY 18-32 | W36: ="FY "&ASRFY&"-"&ASRFY+14 -> #VALUE! | AA36: Date of Exit GPDS Phase (Calendar Year) | AR36: Name and Last Review Date (Calendar Based) | BC36: FY XX - ZZ | BD36: FY XX - ZZ | BE36: FY XX - ZZ | BH36: FY XX - ZZ | BI36: FY XX - ZZ | BJ36: FY XX - ZZ | BL36: Date of Exit GPDS Phase | BN36: Month | BO36: Year
H37: Finance | K37: (MM) | L37: (YY) | O37: MIRR | Q37: =Calc!H176 -> #VALUE! | R37: =Calc!I176 -> 0.20264461 | S37: =Calc!J176 -> NA | U37: =Calc!M176 -> #VALUE! | V37: =Calc!N176 -> 0.26443581 | W37: =Calc!O176 -> NA | AA37: Concept | AC37: =Input!D58 -> N/A | AD37: =Input!E58 -> N/A | AR37: Finance | AU37: (MM) | AV37: (YY) | AY37: MIRR | BL37: Concept | BN37: N/A | BO37: N/A
H38: =Input!B99 -> AA | K38: =Input!D99 -> N/A | L38: =Input!E99 -> N/A | O38: NPV | Q38: =Calc!H177 -> #VALUE! | R38: =Calc!I177 -> 21754.78 | S38: =Calc!J177 -> NA | U38: =Calc!M177 -> #VALUE! | V38: =Calc!N177 -> 101683.22 | W38: =Calc!O177 -> NA | AA38: Definition | AC38: =Input!D59 -> N/A | AD38: =Input!E59 -> N/A | AY38: NPV | BL38: Definition | BN38: N/A | BO38: N/A
H39: Marketing | AR39: Marketing | BN39: Def Exit (FY)
H40: =Input!B101 -> BB | K40: =Input!D101 -> N/A | L40: =Input!E101 -> N/A | O40: Metrics with TV | AA40: Development | AC40: =Input!D61 -> N/A | AD40: =Input!E61 -> N/A | AY40: Metrics with TV | BL40: Development | BN40: N/A | BO40: N/A
H41: R&D | O41: MIRR (with TV) | Q41: =Calc!H185 -> #VALUE! | R41: =Calc!I185 -> 0.39797793 | S41: =Calc!J185 -> NA | AA41: Qualification | AC41: =Input!D62 -> N/A | AD41: =Input!E62 -> N/A | AR41: R&D | AY41: MIRR (with TV) | BL41: Qualification | BN41: N/A | BO41: N/A
H42: =Input!B103 -> CC | K42: =Input!D103 -> N/A | L42: =Input!E103 -> N/A | O42: NPV (with TV) | Q42: =Calc!H186 -> #VALUE! | R42: =Calc!I186 -> 156812.43 | S42: =Calc!J186 -> NA | AA42: Launch | AC42: =Input!D63 -> N/A | AD42: =Input!E63 -> N/A | AY42: NPV (with TV) | BL42: Launch | BN42: N/A | BO42: N/A | BP42: =IF(OR(BN42="Oct",BN42="Nov",BN42="Dec"),BO42+1,BO42) -> N/A
H43: Operations | AR43: Operations | BA43: >> No need to populate
H44: =Input!B105 -> DD | K44: =Input!D105 -> N/A | L44: =Input!E105 -> N/A
B49: Return Metric Calculations SubTotals
...

Sheet HistInfo
B1: Historical Information
B3: This tab intents to keep historical information. At light green highlited cells, please paste figures as value (there are no formulas set).
B6: Financials at GPDS Exit Phases
B8: Definition
B10: Dates (Calendar Year): | AQ10: ** No Action needed on this portion
D11: Mth | E11: Year
B12: Def Exit Approved | D12: NA | E12: NA | G12: Provide when Def Exit was approved | AQ12: H/(L) Table
AQ13: Current Rebaseline vs Definition Exit Commitment
AQ15: Sunk | AR15: =G15 -> 0 | AS15: =H15 -> 0 | AT15: =I15 -> 0 | AU15: =J15 -> 0 | AV15: =K15 -> 0 | AW15: =L15 -> 0 | AX15: =M15 -> 0 | AY15: =N15 -> 0 | ... BU15: =AJ15 -> 0 | BW15: =AM15 -> 0
B17: Incremental Revenue | AQ17: =Calc!AP127-HistInfo!F17 -> 0 | AR17: =Calc!AQ127-HistInfo!G17 -> 0 | AS17: =Calc!AR127-HistInfo!H17 -> 0 | AT17: =Calc!AS127-HistInfo!I17 -> 0 | AU17: =Calc!AT127-HistInfo!J17 -> 0 | AV17: =Calc!AU127-HistInfo!K17 -> 0 | AW17: =Calc!AV127-HistInfo!L17 -> 0 | AX17: =Calc!AW127-HistInfo!M17 -> 0 | ... BU17: =Calc!BT127-HistInfo!AJ17 -> 0 | BW17: =Calc!BW127-HistInfo!AM17 -> 0
B18: Growth %
B19: Category Share | C19: Volume (units)
B20: True Inc Rev (exc. Loss Avoid): PPD
B21: Cost of Sales | AQ21: =Calc!AP131-HistInfo!F21 -> 0 | AR21: =Calc!AQ131-HistInfo!G21 -> 0 | AS21: =Calc!AR131-HistInfo!H21 -> 0 | AT21: =Calc!AS131-HistInfo!I21 -> 0 | AU21: =Calc!AT131-HistInfo!J21 -> 0 | AV21: =Calc!AU131-HistInfo!K21 -> 0 | AW21: =Calc!AV131-HistInfo!L21 -> 0 | AX21: =Calc!AW131-HistInfo!M21 -> 0 | ... BU21: =Calc!BT131-HistInfo!AJ21 -> 0 | BW21: =Calc!BW131-HistInfo!AM21 -> 0
B22: Depreciation | AQ22: =Calc!AP132-HistInfo!F22 -> 0 | AR22: =Calc!AQ132-HistInfo!G22 -> 0 | AS22: =Calc!AR132-HistInfo!H22 -> 0 | AT22: =Calc!AS132-HistInfo!I22 -> 0 | AU22: =Calc!AT132-HistInfo!J22 -> 0 | AV22: =Calc!AU132-HistInfo!K22 -> 0 | AW22: =Calc!AV132-HistInfo!L22 -> 0 | AX22: =Calc!AW132-HistInfo!M22 -> 0 | ... BU22: =Calc!BT132-HistInfo!AJ22 -> 0 | BW22: =Calc!BW132-HistInfo!AM22 -> 0
B23: Gross Profit | AQ23: =Calc!AP133-HistInfo!F23 -> 0 | AR23: =Calc!AQ133-HistInfo!G23 -> 0 | AS23: =Calc!AR133-HistInfo!H23 -> 0 | AT23: =Calc!AS133-HistInfo!I23 -> 0 | AU23: =Calc!AT133-HistInfo!J23 -> 0 | AV23: =Calc!AU133-HistInfo!K23 -> 0 | AW23: =Calc!AV133-HistInfo!L23 -> 0 | AX23: =Calc!AW133-HistInfo!M23 -> 0 | ... BU23: =Calc!BT133-HistInfo!AJ23 -> 0 | BW23: =Calc!BW133-HistInfo!AM23 -> 0
C24: % of Revenue
B25: SSG&A | AQ25: =Calc!AP135-HistInfo!F25 -> 0 | AR25: =Calc!AQ135-HistInfo!G25 -> 0 | AS25: =Calc!AR135-HistInfo!H25 -> 0 | AT25: =Calc!AS135-HistInfo!I25 -> 0 | AU25: =Calc!AT135-HistInfo!J25 -> 0 | AV25: =Calc!AU135-HistInfo!K25 -> 0 | AW25: =Calc!AV135-HistInfo!L25 -> 0 | AX25: =Calc!AW135-HistInfo!M25 -> 0 | ... BU25: =Calc!BT135-HistInfo!AJ25 -> 0 | BW25: =Calc!BW135-HistInfo!AM25 -> 0
B26: R&D | AQ26: =Calc!AP136-HistInfo!F26 -> 0 | AR26: =Calc!AQ136-HistInfo!G26 -> 0 | AS26: =Calc!AR136-HistInfo!H26 -> 0 | AT26: =Calc!AS136-HistInfo!I26 -> 0 | AU26: =Calc!AT136-HistInfo!J26 -> 0 | AV26: =Calc!AU136-HistInfo!K26 -> 0 | AW26: =Calc!AV136-HistInfo!L26 -> 0 | AX26: =Calc!AW136-HistInfo!M26 -> 0 | ... BU26: =Calc!BT136-HistInfo!AJ26 -> 0 | BW26: =Calc!BW136-HistInfo!AM26 -> 0
B27: OIBT | AQ27: =Calc!AP137-HistInfo!F27 -> 0 | AR27: =Calc!AQ137-HistInfo!G27 -> 0 | AS27: =Calc!AR137-HistInfo!H27 -> 0 | AT27: =Calc!AS137-HistInfo!I27 -> 0 | AU27: =Calc!AT137-HistInfo!J27 -> 0 | AV27: =Calc!AU137-HistInfo!K27 -> 0 | AW27: =Calc!AV137-HistInfo!L27 -> 0 | AX27: =Calc!AW137-HistInfo!M27 -> 0 | ... BU27: =Calc!BT137-HistInfo!AJ27 -> 0 | BW27: =Calc!BW137-HistInfo!AM27 -> 0
C28: % of Revenue
B29: Other (Inc) / Exp | AQ29: =Calc!AP139-HistInfo!F29 -> 0 | AR29: =Calc!AQ139-HistInfo!G29 -> 0 | AS29: =Calc!AR139-HistInfo!H29 -> 0 | AT29: =Calc!AS139-HistInfo!I29 -> 0 | AU29: =Calc!AT139-HistInfo!J29 -> 0 | AV29: =Calc!AU139-HistInfo!K29 -> 0 | AW29: =Calc!AV139-HistInfo!L29 -> 0 | AX29: =Calc!AW139-HistInfo!M29 -> 0 | ... BU29: =Calc!BT139-HistInfo!AJ29 -> 0 | BW29: =Calc!BW139-HistInfo!AM29 -> 0
B30: Tax Exp / (Ben) | AQ30: =Calc!AP140-HistInfo!F30 -> 0 | AR30: =Calc!AQ140-HistInfo!G30 -> 0 | AS30: =Calc!AR140-HistInfo!H30 -> 0 | AT30: =Calc!AS140-HistInfo!I30 -> 0 | AU30: =Calc!AT140-HistInfo!J30 -> 0 | AV30: =Calc!AU140-HistInfo!K30 -> 0 | AW30: =Calc!AV140-HistInfo!L30 -> 0 | AX30: =Calc!AW140-HistInfo!M30 -> 0 | ... BU30: =Calc!BT140-HistInfo!AJ30 -> 0 | BW30: =Calc!BW140-HistInfo!AM30 -> 0
B31: Net Income | AQ31: =Calc!AP141-HistInfo!F31 -> 0 | AR31: =Calc!AQ141-HistInfo!G31 -> 0 | AS31: =Calc!AR141-HistInfo!H31 -> 0 | AT31: =Calc!AS141-HistInfo!I31 -> 0 | AU31: =Calc!AT141-HistInfo!J31 -> 0 | AV31: =Calc!AU141-HistInfo!K31 -> 0 | AW31: =Calc!AV141-HistInfo!L31 -> 0 | AX31: =Calc!AW141-HistInfo!M31 -> 0 | ... BU31: =Calc!BT141-HistInfo!AJ31 -> 0 | BW31: =Calc!BW141-HistInfo!AM31 -> 0
C32: % of Revenue
B33: Capital | AQ33: =Calc!AP143-HistInfo!F33 -> 0 | AR33: =Calc!AQ143-HistInfo!G33 -> 0 | AS33: =Calc!AR143-HistInfo!H33 -> 0 | AT33: =Calc!AS143-HistInfo!I33 -> 0 | AU33: =Calc!AT143-HistInfo!J33 -> 0 | AV33: =Calc!AU143-HistInfo!K33 -> 0 | AW33: =Calc!AV143-HistInfo!L33 -> 0 | AX33: =Calc!AW143-HistInfo!M33 -> 0 | ... BU33: =Calc!BT143-HistInfo!AJ33 -> 0 | BW33: =Calc!BW143-HistInfo!AM33 -> 0
B34: Increase in Working Capital | AQ34: =Calc!AP144-HistInfo!F34 -> 0 | AR34: =Calc!AQ144-HistInfo!G34 -> 0 | AS34: =Calc!AR144-HistInfo!H34 -> 0 | AT34: =Calc!AS144-HistInfo!I34 -> 0 | AU34: =Calc!AT144-HistInfo!J34 -> 0 | AV34: =Calc!AU144-HistInfo!K34 -> 0 | AW34: =Calc!AV144-HistInfo!L34 -> 0 | AX34: =Calc!AW144-HistInfo!M34 -> 0 | ... BU34: =Calc!BT144-HistInfo!AJ34 -> 0 | BW34: =Calc!BW144-HistInfo!AM34 -> 0
B35: Free Cash Flow* | AQ35: =Calc!AP145-HistInfo!F35 -> 0 | AR35: =Calc!AQ145-HistInfo!G35 -> 0 | AS35: =Calc!AR145-HistInfo!H35 -> 0 | AT35: =Calc!AS145-HistInfo!I35 -> 0 | AU35: =Calc!AT145-HistInfo!J35 -> 0 | AV35: =Calc!AU145-HistInfo!K35 -> 0 | AW35: =Calc!AV145-HistInfo!L35 -> 0 | AX35: =Calc!AW145-HistInfo!M35 -> 0 | ... BU35: =Calc!BT145-HistInfo!AJ35 -> 0 | BW35: =Calc!BW145-HistInfo!AM35 -> 0
C36: % of Revenue
H40: Def Exit Approvers and Dates: | O40: Def Exit Commitment | V40: Actual / Expected Exit GPDS Phases, as project exited Definition
H41: Name and Last Review Date (Calendar Year) | Q41: 10 Yrs | R41: 15 Yrs
H42: Finance | K42: Mth | L42: Year | Q42: FY XX - ZZ | R42: FY XX - ZZ | V42: Dates (Calendar Year) | X42: Mth | Y42: Year | AA42: FY (equivalent)
H43: <Enter Name> | K43: NA | L43: NA | O43: MIRR | V43: Concept | X43: N/A | Y43: N/A | AA43: ="FY"&IF(OR(X43="Oct",X43="Nov",X43="Dec"),Y43+1,Y43) -> FYN/A
H44: Marketing | O44: NPV | V44: Definition | X44: N/A | Y44: N/A | AA44: ="FY"&IF(OR(X44="Oct",X44="Nov",X44="Dec"),Y44+1,Y44) -> FYN/A | AB44: =RIGHT(AA44,2)*1 -> #VALUE!
H45: <Enter Name> | K45: NA | L45: NA | O45: MIRR (with TV) | X45: Def Exit Commt
H46: R&D | O46: NPV (with TV) | V46: Development | X46: N/A | Y46: N/A | AA46: ="FY"&IF(OR(X46="Oct",X46="Nov",X46="Dec"),Y46+1,Y46) -> FYN/A
H47: <Enter Name> | K47: NA | L47: NA | V47: Qualification | X47: N/A | Y47: N/A | AA47: ="FY"&IF(OR(X47="Oct",X47="Nov",X47="Dec"),Y47+1,Y47) -> FYN/A
H48: Operations | O48: Tax Rate | V48: Launch | X48: N/A | Y48: N/A | AA48: ="FY"&IF(OR(X48="Oct",X48="Nov",X48="Dec"),Y48+1,Y48) -> FYN/A | AB48: =RIGHT(AA48,2)*1 -> #VALUE!
H49: <Enter Name> | K49: NA | L49: NA | O49: Discount Rate
B54: Development
...

Sheet Capital_Dep
B2: Capital and Depreciation: Actual / Projections | AN2: ="Capital and Depreciation: "&Comp -> Capital and Depreciation: Def Exit
H4: =ProjStartFY -> 18 | I4: =ProjStartFY+1 -> 19 | J4: =ProjStartFY+2 -> 20 | K4: =ProjStartFY+3 -> 21 | L4: =ProjStartFY+4 -> 22 | M4: =ProjStartFY+5 -> 23 | N4: =ProjStartFY+6 -> 24 | O4: =ProjStartFY+7 -> 25 | P4: =ProjStartFY+8 -> 26 | Q4: =ProjStartFY+9 -> 27 | R4: =ProjStartFY+10 -> 28 | S4: =ProjStartFY+11 -> 29 | T4: =ProjStartFY+12 -> 30 | U4: =ProjStartFY+13 -> 31 | V4: =ProjStartFY+14 -> 32 | W4: =ProjStartFY+15 -> 33 | X4: =ProjStartFY+16 -> 34 | Y4: =ProjStartFY+17 -> 35 | Z4: =ProjStartFY+18 -> 36 | AA4: =ProjStartFY+19 -> 37 | AB4: =ProjStartFY+20 -> 38 | AC4: =ProjStartFY+21 -> 39 | AD4: =ProjStartFY+22 -> 40 | AE4: =ProjStartFY+23 -> 41 | AF4: =ProjStartFY+24 -> 42 | AG4: =ProjStartFY+25 -> 43 | AH4: =ProjStartFY+26 -> 44 | AI4: =ProjStartFY+27 -> 45 | AJ4: =ProjStartFY+28 -> 46 | AT4: =ProjStartFY -> 18 | AU4: =ProjStartFY+1 -> 19 | AV4: =ProjStartFY+2 -> 20 | AW4: =ProjStartFY+3 -> 21 | AX4: =ProjStartFY+4 -> 22 | AY4: =ProjStartFY+5 -> 23 | AZ4: =ProjStartFY+6 -> 24 | BA4: =ProjStartFY+7 -> 25 | BB4: =ProjStartFY+8 -> 26 | BC4: =ProjStartFY+9 -> 27 | BD4: =ProjStartFY+10 -> 28 | BE4: =ProjStartFY+11 -> 29 | BF4: =ProjStartFY+12 -> 30 | BG4: =ProjStartFY+13 -> 31 | BH4: =ProjStartFY+14 -> 32 | BI4: =ProjStartFY+15 -> 33 | BJ4: =ProjStartFY+16 -> 34 | BK4: =ProjStartFY+17 -> 35 | BL4: =ProjStartFY+18 -> 36 | BM4: =ProjStartFY+19 -> 37 | BN4: =ProjStartFY+20 -> 38 | BO4: =ProjStartFY+21 -> 39 | BP4: =ProjStartFY+22 -> 40 | BQ4: =ProjStartFY+23 -> 41 | BR4: =ProjStartFY+24 -> 42 | BS4: =ProjStartFY+25 -> 43 | BT4: =ProjStartFY+26 -> 44 | BU4: =ProjStartFY+27 -> 45 | BV4: =ProjStartFY+28 -> 46
B5: Item | C5: Capital Requirements | D5: Asset Useful Life (years) | E5: Service Mth | F5: Service Year | G5: FY | H5: ="FY"&ProjStartFY -> FY18 | I5: ="FY"&ProjStartFY+1 -> FY19 | J5: ="FY"&ProjStartFY+2 -> FY20 | K5: ="FY"&ProjStartFY+3 -> FY21 | L5: ="FY"&ProjStartFY+4 -> FY22 | M5: ="FY"&ProjStartFY+5 -> FY23 | N5: ="FY"&ProjStartFY+6 -> FY24 | O5: ="FY"&ProjStartFY+7 -> FY25 | P5: ="FY"&ProjStartFY+8 -> FY26 | Q5: ="FY"&ProjStartFY+9 -> FY27 | R5: ="FY"&ProjStartFY+10 -> FY28 | S5: ="FY"&ProjStartFY+11 -> FY29 | T5: ="FY"&ProjStartFY+12 -> FY30 | U5: ="FY"&ProjStartFY+13 -> FY31 | V5: ="FY"&ProjStartFY+14 -> FY32 | W5: ="FY"&ProjStartFY+15 -> FY33 | X5: ="FY"&ProjStartFY+16 -> FY34 | Y5: ="FY"&ProjStartFY+17 -> FY35 | Z5: ="FY"&ProjStartFY+18 -> FY36 | AA5: ="FY"&ProjStartFY+19 -> FY37 | AB5: ="FY"&ProjStartFY+20 -> FY38 | AC5: ="FY"&ProjStartFY+21 -> FY39 | AD5: ="FY"&ProjStartFY+22 -> FY40 | AE5: ="FY"&ProjStartFY+23 -> FY41 | AF5: ="FY"&ProjStartFY+24 -> FY42 | AG5: ="FY"&ProjStartFY+25 -> FY43 | AH5: ="FY"&ProjStartFY+26 -> FY44 | AI5: ="FY"&ProjStartFY+27 -> FY45 | AJ5: ="FY"&ProjStartFY+28 -> FY46 | AK5: Total | AN5: Item | AO5: Capital Requirements | AP5: Asset Useful Life (years) | AQ5: Service Mth | AR5: Service Year | AS5: FY | AT5: ="FY"&ProjStartFY -> FY18 | AU5: ="FY"&ProjStartFY+1 -> FY19 | AV5: ="FY"&ProjStartFY+2 -> FY20 | AW5: ="FY"&ProjStartFY+3 -> FY21 | AX5: ="FY"&ProjStartFY+4 -> FY22 | AY5: ="FY"&ProjStartFY+5 -> FY23 | AZ5: ="FY"&ProjStartFY+6 -> FY24 | BA5: ="FY"&ProjStartFY+7 -> FY25 | BB5: ="FY"&ProjStartFY+8 -> FY26 | BC5: ="FY"&ProjStartFY+9 -> FY27 | BD5: ="FY"&ProjStartFY+10 -> FY28 | BE5: ="FY"&ProjStartFY+11 -> FY29 | BF5: ="FY"&ProjStartFY+12 -> FY30 | BG5: ="FY"&ProjStartFY+13 -> FY31 | BH5: ="FY"&ProjStartFY+14 -> FY32 | BI5: ="FY"&ProjStartFY+15 -> FY33 | BJ5: ="FY"&ProjStartFY+16 -> FY34 | BK5: ="FY"&ProjStartFY+17 -> FY35 | BL5: ="FY"&ProjStartFY+18 -> FY36 | BM5: ="FY"&ProjStartFY+19 -> FY37 | BN5: ="FY"&ProjStartFY+20 -> FY38 | BO5: ="FY"&ProjStartFY+21 -> FY39 | BP5: ="FY"&ProjStartFY+22 -> FY40 | BQ5: ="FY"&ProjStartFY+23 -> FY41 | BR5: ="FY"&ProjStartFY+24 -> FY42 | BS5: ="FY"&ProjStartFY+25 -> FY43 | BT5: ="FY"&ProjStartFY+26 -> FY44 | BU5: ="FY"&ProjStartFY+27 -> FY45 | BV5: ="FY"&ProjStartFY+28 -> FY46 | BW5: Total
B6: 1 | E6: N/A | F6: N/A | G6: =IF(OR(E6="N/A",F6="N/A"),0,IF(OR(E6="Oct",E6="Nov",E6="Dec"),F6+1,F6)) -> 0 | AK6: =SUM(H6:AJ6) -> 0 | AN6: 1 | AO6: AAA - Assembly Line | AQ6: N/A | AR6: N/A | AS6: =IF(OR(AQ6="N/A",AR6="N/A"),0,IF(OR(AQ6="Oct",AQ6="Nov",AQ6="Dec"),AR6+1,AR6)) -> 0 | BW6: =SUM(AT6:BV6) -> 0
B7: =B6+1 -> 2 | E7: N/A | F7: N/A | G7: =IF(OR(E7="N/A",F7="N/A"),0,IF(OR(E7="Oct",E7="Nov",E7="Dec"),F7+1,F7)) -> 0 | AK7: =SUM(H7:AJ7) -> 0 | AN7: =AN6+1 -> 2 | AQ7: N/A | AR7: N/A | AS7: =IF(OR(AQ7="N/A",AR7="N/A"),0,IF(OR(AQ7="Oct",AQ7="Nov",AQ7="Dec"),AR7+1,AR7)) -> 0 | BW7: =SUM(AT7:BV7) -> 0
B8: =B7+1 -> 3 | E8: N/A | F8: N/A | G8: =IF(OR(E8="N/A",F8="N/A"),0,IF(OR(E8="Oct",E8="Nov",E8="Dec"),F8+1,F8)) -> 0 | AK8: =SUM(H8:AJ8) -> 0 | AN8: =AN7+1 -> 3 | AQ8: N/A | AR8: N/A | AS8: =IF(OR(AQ8="N/A",AR8="N/A"),0,IF(OR(AQ8="Oct",AQ8="Nov",AQ8="Dec"),AR8+1,AR8)) -> 0 | BW8: =SUM(AT8:BV8) -> 0
B9: =B8+1 -> 4 | E9: N/A | F9: N/A | G9: =IF(OR(E9="N/A",F9="N/A"),0,IF(OR(E9="Oct",E9="Nov",E9="Dec"),F9+1,F9)) -> 0 | AK9: =SUM(H9:AJ9) -> 0 | AN9: =AN8+1 -> 4 | AQ9: N/A | AR9: N/A | AS9: =IF(OR(AQ9="N/A",AR9="N/A"),0,IF(OR(AQ9="Oct",AQ9="Nov",AQ9="Dec"),AR9+1,AR9)) -> 0 | BW9: =SUM(AT9:BV9) -> 0
B10: =B9+1 -> 5 | E10: N/A | F10: N/A | G10: =IF(OR(E10="N/A",F10="N/A"),0,IF(OR(E10="Oct",E10="Nov",E10="Dec"),F10+1,F10)) -> 0 | AK10: =SUM(H10:AJ10) -> 0 | AN10: =AN9+1 -> 5 | AQ10: N/A | AR10: N/A | AS10: =IF(OR(AQ10="N/A",AR10="N/A"),0,IF(OR(AQ10="Oct",AQ10="Nov",AQ10="Dec"),AR10+1,AR10)) -> 0 | BW10: =SUM(AT10:BV10) -> 0
B11: =B10+1 -> 6 | E11: N/A | F11: N/A | G11: =IF(OR(E11="N/A",F11="N/A"),0,IF(OR(E11="Oct",E11="Nov",E11="Dec"),F11+1,F11)) -> 0 | AK11: =SUM(H11:AJ11) -> 0 | AN11: =AN10+1 -> 6 | AQ11: N/A | AR11: N/A | AS11: =IF(OR(AQ11="N/A",AR11="N/A"),0,IF(OR(AQ11="Oct",AQ11="Nov",AQ11="Dec"),AR11+1,AR11)) -> 0 | BW11: =SUM(AT11:BV11) -> 0
B12: =B11+1 -> 7 | E12: N/A | F12: N/A | G12: =IF(OR(E12="N/A",F12="N/A"),0,IF(OR(E12="Oct",E12="Nov",E12="Dec"),F12+1,F12)) -> 0 | AK12: =SUM(H12:AJ12) -> 0 | AN12: =AN11+1 -> 7 | AQ12: N/A | AR12: N/A | AS12: =IF(OR(AQ12="N/A",AR12="N/A"),0,IF(OR(AQ12="Oct",AQ12="Nov",AQ12="Dec"),AR12+1,AR12)) -> 0 | BW12: =SUM(AT12:BV12) -> 0
B13: =B12+1 -> 8 | E13: N/A | F13: N/A | G13: =IF(OR(E13="N/A",F13="N/A"),0,IF(OR(E13="Oct",E13="Nov",E13="Dec"),F13+1,F13)) -> 0 | AK13: =SUM(H13:AJ13) -> 0 | AN13: =AN12+1 -> 8 | AQ13: N/A | AR13: N/A | AS13: =IF(OR(AQ13="N/A",AR13="N/A"),0,IF(OR(AQ13="Oct",AQ13="Nov",AQ13="Dec"),AR13+1,AR13)) -> 0 | BW13: =SUM(AT13:BV13) -> 0
B14: =B13+1 -> 9 | E14: N/A | F14: N/A | G14: =IF(OR(E14="N/A",F14="N/A"),0,IF(OR(E14="Oct",E14="Nov",E14="Dec"),F14+1,F14)) -> 0 | AK14: =SUM(H14:AJ14) -> 0 | AN14: =AN13+1 -> 9 | AQ14: N/A | AR14: N/A | AS14: =IF(OR(AQ14="N/A",AR14="N/A"),0,IF(OR(AQ14="Oct",AQ14="Nov",AQ14="Dec"),AR14+1,AR14)) -> 0 | BW14: =SUM(AT14:BV14) -> 0
B15: =B14+1 -> 10 | C15: JJJ | E15: N/A | F15: N/A | G15: =IF(OR(E15="N/A",F15="N/A"),0,IF(OR(E15="Oct",E15="Nov",E15="Dec"),F15+1,F15)) -> 0 | AK15: =SUM(H15:AJ15) -> 0 | AN15: =AN14+1 -> 10 | AQ15: N/A | AR15: N/A | AS15: =IF(OR(AQ15="N/A",AR15="N/A"),0,IF(OR(AQ15="Oct",AQ15="Nov",AQ15="Dec"),AR15+1,AR15)) -> 0 | BW15: =SUM(AT15:BV15) -> 0
B16: =B15+1 -> 11 | C16: KKK | E16: N/A | F16: N/A | G16: =IF(OR(E16="N/A",F16="N/A"),0,IF(OR(E16="Oct",E16="Nov",E16="Dec"),F16+1,F16)) -> 0 | AK16: =SUM(H16:AJ16) -> 0 | AN16: =AN15+1 -> 11 | AQ16: N/A | AR16: N/A | AS16: =IF(OR(AQ16="N/A",AR16="N/A"),0,IF(OR(AQ16="Oct",AQ16="Nov",AQ16="Dec"),AR16+1,AR16)) -> 0 | BW16: =SUM(AT16:BV16) -> 0
B17: =B16+1 -> 12 | C17: LLL | E17: N/A | F17: N/A | G17: =IF(OR(E17="N/A",F17="N/A"),0,IF(OR(E17="Oct",E17="Nov",E17="Dec"),F17+1,F17)) -> 0 | AK17: =SUM(H17:AJ17) -> 0 | AN17: =AN16+1 -> 12 | AO17: LLL | AQ17: N/A | AR17: N/A | AS17: =IF(OR(AQ17="N/A",AR17="N/A"),0,IF(OR(AQ17="Oct",AQ17="Nov",AQ17="Dec"),AR17+1,AR17)) -> 0 | BW17: =SUM(AT17:BV17) -> 0
B18: =B17+1 -> 13 | C18: MMM | E18: N/A | F18: N/A | G18: =IF(OR(E18="N/A",F18="N/A"),0,IF(OR(E18="Oct",E18="Nov",E18="Dec"),F18+1,F18)) -> 0 | AK18: =SUM(H18:AJ18) -> 0 | AN18: =AN17+1 -> 13 | AO18: MMM | AQ18: N/A | AR18: N/A | AS18: =IF(OR(AQ18="N/A",AR18="N/A"),0,IF(OR(AQ18="Oct",AQ18="Nov",AQ18="Dec"),AR18+1,AR18)) -> 0 | BW18: =SUM(AT18:BV18) -> 0
B19: =B18+1 -> 14 | C19: NNN | E19: N/A | F19: N/A | G19: =IF(OR(E19="N/A",F19="N/A"),0,IF(OR(E19="Oct",E19="Nov",E19="Dec"),F19+1,F19)) -> 0 | AK19: =SUM(H19:AJ19) -> 0 | AN19: =AN18+1 -> 14 | AO19: NNN | AQ19: N/A | AR19: N/A | AS19: =IF(OR(AQ19="N/A",AR19="N/A"),0,IF(OR(AQ19="Oct",AQ19="Nov",AQ19="Dec"),AR19+1,AR19)) -> 0 | BW19: =SUM(AT19:BV19) -> 0
B20: =B19+1 -> 15 | C20: OOO | E20: N/A | F20: N/A | G20: =IF(OR(E20="N/A",F20="N/A"),0,IF(OR(E20="Oct",E20="Nov",E20="Dec"),F20+1,F20)) -> 0 | AK20: =SUM(H20:AJ20) -> 0 | AN20: =AN19+1 -> 15 | AO20: OOO | AQ20: N/A | AR20: N/A | AS20: =IF(OR(AQ20="N/A",AR20="N/A"),0,IF(OR(AQ20="Oct",AQ20="Nov",AQ20="Dec"),AR20+1,AR20)) -> 0 | BW20: =SUM(AT20:BV20) -> 0
B21: =B20+1 -> 16 | C21: PPP | E21: N/A | F21: N/A | G21: =IF(OR(E21="N/A",F21="N/A"),0,IF(OR(E21="Oct",E21="Nov",E21="Dec"),F21+1,F21)) -> 0 | AK21: =SUM(H21:AJ21) -> 0 | AN21: =AN20+1 -> 16 | AO21: PPP | AQ21: N/A | AR21: N/A | AS21: =IF(OR(AQ21="N/A",AR21="N/A"),0,IF(OR(AQ21="Oct",AQ21="Nov",AQ21="Dec"),AR21+1,AR21)) -> 0 | BW21: =SUM(AT21:BV21) -> 0
B22: =B21+1 -> 17 | C22: QQQ | E22: N/A | F22: N/A | G22: =IF(OR(E22="N/A",F22="N/A"),0,IF(OR(E22="Oct",E22="Nov",E22="Dec"),F22+1,F22)) -> 0 | AK22: =SUM(H22:AJ22) -> 0 | AN22: =AN21+1 -> 17 | AO22: QQQ | AQ22: N/A | AR22: N/A | AS22: =IF(OR(AQ22="N/A",AR22="N/A"),0,IF(OR(AQ22="Oct",AQ22="Nov",AQ22="Dec"),AR22+1,AR22)) -> 0 | BW22: =SUM(AT22:BV22) -> 0
B23: =B22+1 -> 18 | C23: RRR | E23: N/A | F23: N/A | G23: =IF(OR(E23="N/A",F23="N/A"),0,IF(OR(E23="Oct",E23="Nov",E23="Dec"),F23+1,F23)) -> 0 | AK23: =SUM(H23:AJ23) -> 0 | AN23: =AN22+1 -> 18 | AO23: RRR | AQ23: N/A | AR23: N/A | AS23: =IF(OR(AQ23="N/A",AR23="N/A"),0,IF(OR(AQ23="Oct",AQ23="Nov",AQ23="Dec"),AR23+1,AR23)) -> 0 | BW23: =SUM(AT23:BV23) -> 0
B24: =B23+1 -> 19 | C24: SSS | E24: N/A | F24: N/A | G24: =IF(OR(E24="N/A",F24="N/A"),0,IF(OR(E24="Oct",E24="Nov",E24="Dec"),F24+1,F24)) -> 0 | AK24: =SUM(H24:AJ24) -> 0 | AN24: =AN23+1 -> 19 | AO24: SSS | AQ24: N/A | AR24: N/A | AS24: =IF(OR(AQ24="N/A",AR24="N/A"),0,IF(OR(AQ24="Oct",AQ24="Nov",AQ24="Dec"),AR24+1,AR24)) -> 0 | BW24: =SUM(AT24:BV24) -> 0
B25: =B24+1 -> 20 | C25: TTT | E25: N/A | F25: N/A | G25: =IF(OR(E25="N/A",F25="N/A"),0,IF(OR(E25="Oct",E25="Nov",E25="Dec"),F25+1,F25)) -> 0 | AK25: =SUM(H25:AJ25) -> 0 | AN25: =AN24+1 -> 20 | AO25: TTT | AQ25: N/A | AR25: N/A | AS25: =IF(OR(AQ25="N/A",AR25="N/A"),0,IF(OR(AQ25="Oct",AQ25="Nov",AQ25="Dec"),AR25+1,AR25)) -> 0 | BW25: =SUM(AT25:BV25) -> 0
B26: =B25+1 -> 21 | C26: UUU | E26: N/A | F26: N/A | G26: =IF(OR(E26="N/A",F26="N/A"),0,IF(OR(E26="Oct",E26="Nov",E26="Dec"),F26+1,F26)) -> 0 | AK26: =SUM(H26:AJ26) -> 0 | AN26: =AN25+1 -> 21 | AO26: UUU | AQ26: N/A | AR26: N/A | AS26: =IF(OR(AQ26="N/A",AR26="N/A"),0,IF(OR(AQ26="Oct",AQ26="Nov",AQ26="Dec"),AR26+1,AR26)) -> 0 | BW26: =SUM(AT26:BV26) -> 0
B27: =B26+1 -> 22 | C27: VVV | E27: N/A | F27: N/A | G27: =IF(OR(E27="N/A",F27="N/A"),0,IF(OR(E27="Oct",E27="Nov",E27="Dec"),F27+1,F27)) -> 0 | AK27: =SUM(H27:AJ27) -> 0 | AN27: =AN26+1 -> 22 | AO27: VVV | AQ27: N/A | AR27: N/A | AS27: =IF(OR(AQ27="N/A",AR27="N/A"),0,IF(OR(AQ27="Oct",AQ27="Nov",AQ27="Dec"),AR27+1,AR27)) -> 0 | BW27: =SUM(AT27:BV27) -> 0
B28: =B27+1 -> 23 | C28: WWW | E28: N/A | F28: N/A | G28: =IF(OR(E28="N/A",F28="N/A"),0,IF(OR(E28="Oct",E28="Nov",E28="Dec"),F28+1,F28)) -> 0 | AK28: =SUM(H28:AJ28) -> 0 | AN28: =AN27+1 -> 23 | AO28: WWW | AQ28: N/A | AR28: N/A | AS28: =IF(OR(AQ28="N/A",AR28="N/A"),0,IF(OR(AQ28="Oct",AQ28="Nov",AQ28="Dec"),AR28+1,AR28)) -> 0 | BW28: =SUM(AT28:BV28) -> 0
... B35: =B34+1 -> 30 | C35: DD1 | E35: N/A | F35: N/A | G35: =IF(OR(E35="N/A",F35="N/A"),0,IF(OR(E35="Oct",E35="Nov",E35="Dec"),F35+1,F35)) -> 0 | AK35: =SUM(H35:AJ35) -> 0 | AN35: =AN34+1 -> 30 | AO35: DD1 | AQ35: N/A | AR35: N/A | AS35: =IF(OR(AQ35="N/A",AR35="N/A"),0,IF(OR(AQ35="Oct",AQ35="Nov",AQ35="Dec"),AR35+1,AR35)) -> 0 | BW35: =SUM(AT35:BV35) -> 0
C36: Total Capital Employed | H36: =SUM(H6:H35) -> 0 | I36: =SUM(I6:I35) -> 0 | J36: =SUM(J6:J35) -> 0 | K36: =SUM(K6:K35) -> 0 | L36: =SUM(L6:L35) -> 0 | M36: =SUM(M6:M35) -> 0 | N36: =SUM(N6:N35) -> 0 | O36: =SUM(O6:O35) -> 0 | ... AK36: =SUM(AK6:AK35) -> 0 | AO36: Total Capital Employed | AT36: =SUM(AT6:AT35) -> 0 | AU36: =SUM(AU6:AU35) -> 0 | AV36: =SUM(AV6:AV35) -> 0 | AW36: =SUM(AW6:AW35) -> 0 | AX36: =SUM(AX6:AX35) -> 0 | AY36: =SUM(AY6:AY35) -> 0 | AZ36: =SUM(AZ6:AZ35) -> 0 | BA36: =SUM(BA6:BA35) -> 0 | ... BW36: =SUM(BW6:BW35) -> 0
B38: Item | C38: Depreciation for New Line | D38: Monthly Depreciation | H38: =+H5 -> FY18 | I38: =+I5 -> FY19 | J38: =+J5 -> FY20 | K38: =+K5 -> FY21 | L38: =+L5 -> FY22 | M38: =+M5 -> FY23 | N38: =+N5 -> FY24 | O38: =+O5 -> FY25 | ... AJ38: =+AJ5 -> FY46 | AK38: Total | AN38: Item | AO38: Depreciation for New Line | AP38: Monthly Depreciation | AT38: =+AT5 -> FY18 | AU38: =+AU5 -> FY19 | AV38: =+AV5 -> FY20 | AW38: =+AW5 -> FY21 | AX38: =+AX5 -> FY22 | AY38: =+AY5 -> FY23 | AZ38: =+AZ5 -> FY24 | BA38: =+BA5 -> FY25 | ... BV38: =+BV5 -> FY46 | BW38: Total
B39: =B6 -> 1 | C39: =C6 -> 0 | D39: =IFERROR(AK6/D6/12,0) -> 0 | H39: =IF(H$4=$G6,$D39*(12-VLOOKUP($E6,$E$79:$F$90,2,0)),IF(AND(H$4>$G6,H$4<($G6+$D6)),$D39*12,IF(H$4=($G6+$D6),$D39*VLOOKUP($E6,$E$79:$F$90,2,0),0))) -> 0 | I39: =IF(I$4=$G6,$D39*(12-VLOOKUP($E6,$E$79:$F$90,2,0)),IF(AND(I$4>$G6,I$4<($G6+$D6)),$D39*12,IF(I$4=($G6+$D6),$D39*VLOOKUP($E6,$E$79:$F$90,2,0),0))) -> 0 | J39: =IF(J$4=$G6,$D39*(12-VLOOKUP($E6,$E$79:$F$90,2,0)),IF(AND(J$4>$G6,J$4<($G6+$D6)),$D39*12,IF(J$4=($G6+$D6),$D39*VLOOKUP($E6,$E$79:$F$90,2,0),0))) -> 0 | K39: =IF(K$4=$G6,$D39*(12-VLOOKUP($E6,$E$79:$F$90,2,0)),IF(AND(K$4>$G6,K$4<($G6+$D6)),$D39*12,IF(K$4=($G6+$D6),$D39*VLOOKUP($E6,$E$79:$F$90,2,0),0))) -> 0 | L39: =IF(L$4=$G6,$D39*(12-VLOOKUP($E6,$E$79:$F$90,2,0)),IF(AND(L$4>$G6,L$4<($G6+$D6)),$D39*12,IF(L$4=($G6+$D6),$D39*VLOOKUP($E6,$E$79:$F$90,2,0),0))) -> 0 | M39: =IF(M$4=$G6,$D39*(12-VLOOKUP($E6,$E$79:$F$90,2,0)),IF(AND(M$4>$G6,M$4<($G6+$D6)),$D39*12,IF(M$4=($G6+$D6),$D39*VLOOKUP($E6,$E$79:$F$90,2,0),0))) -> 0 | N39: =IF(N$4=$G6,$D39*(12-VLOOKUP($E6,$E$79:$F$90,2,0)),IF(AND(N$4>$G6,N$4<($G6+$D6)),$D39*12,IF(N$4=($G6+$D6),$D39*VLOOKUP($E6,$E$79:$F$90,2,0),0))) -> 0 | O39: =IF(O$4=$G6,$D39*(12-VLOOKUP($E6,$E$79:$F$90,2,0)),IF(AND(O$4>$G6,O$4<($G6+$D6)),$D39*12,IF(O$4=($G6+$D6),$D39*VLOOKUP($E6,$E$79:$F$90,2,0),0))) -> 0 | ... AJ39: =IF(AJ$4=$G6,$D39*(12-VLOOKUP($E6,$E$79:$F$90,2,0)),IF(AND(AJ$4>$G6,AJ$4<($G6+$D6)),$D39*12,IF(AJ$4=($G6+$D6),$D39*VLOOKUP($E6,$E$79:$F$90,2,0),0))) -> 0 | AK39: =SUM(H39:AJ39) -> 0 | AN39: =AN6 -> 1 | AO39: =AO6 -> AAA - Assembly Line | AP39: =IFERROR(BW6/AP6/12,0) -> 0 | AT39: =IF(AT$4=$AS6,$AP39*(12-VLOOKUP($AQ6,$E$79:$F$90,2,0)),IF(AND(AT$4>$AS6,AT$4<($AS6+$AP6)),$AP39*12,IF(AT$4=($AS6+$AP6),$AP39*VLOOKUP($AQ6,$E$79:$F$90,2,0),0))) -> 0 | AU39: =IF(AU$4=$AS6,$AP39*(12-VLOOKUP($AQ6,$E$79:$F$90,2,0)),IF(AND(AU$4>$AS6,AU$4<($AS6+$AP6)),$AP39*12,IF(AU$4=($AS6+$AP6),$AP39*VLOOKUP($AQ6,$E$79:$F$90,2,0),0))) -> 0 | AV39: =IF(AV$4=$AS6,$AP39*(12-VLOOKUP($AQ6,$E$79:$F$90,2,0)),IF(AND(AV$4>$AS6,AV$4<($AS6+$AP6)),$AP39*12,IF(AV$4=($AS6+$AP6),$AP39*VLOOKUP($AQ6,$E$79:$F$90,2,0),0))) -> 0 | AW39: =IF(AW$4=$AS6,$AP39*(12-VLOOKUP($AQ6,$E$79:$F$90,2,0)),IF(AND(AW$4>$AS6,AW$4<($AS6+$AP6)),$AP39*12,IF(AW$4=($AS6+$AP6),$AP39*VLOOKUP($AQ6,$E$79:$F$90,2,0),0))) -> 0 | AX39: =IF(AX$4=$AS6,$AP39*(12-VLOOKUP($AQ6,$E$79:$F$90,2,0)),IF(AND(AX$4>$AS6,AX$4<($AS6+$AP6)),$AP39*12,IF(AX$4=($AS6+$AP6),$AP39*VLOOKUP($AQ6,$E$79:$F$90,2,0),0))) -> 0 | AY39: =IF(AY$4=$AS6,$AP39*(12-VLOOKUP($AQ6,$E$79:$F$90,2,0)),IF(AND(AY$4>$AS6,AY$4<($AS6+$AP6)),$AP39*12,IF(AY$4=($AS6+$AP6),$AP39*VLOOKUP($AQ6,$E$79:$F$90,2,0),0))) -> 0 | AZ39: =IF(AZ$4=$AS6,$AP39*(12-VLOOKUP($AQ6,$E$79:$F$90,2,0)),IF(AND(AZ$4>$AS6,AZ$4<($AS6+$AP6)),$AP39*12,IF(AZ$4=($AS6+$AP6),$AP39*VLOOKUP($AQ6,$E$79:$F$90,2,0),0))) -> 0 | BA39: =IF(BA$4=$AS6,$AP39*(12-VLOOKUP($AQ6,$E$79:$F$90,2,0)),IF(AND(BA$4>$AS6,BA$4<($AS6+$AP6)),$AP39*12,IF(BA$4=($AS6+$AP6),$AP39*VLOOKUP($AQ6,$E$79:$F$90,2,0),0))) -> 0 | ... BV39: =IF(BV$4=$AS6,$AP39*(12-VLOOKUP($AQ6,$E$79:$F$90,2,0)),IF(AND(BV$4>$AS6,BV$4<($AS6+$AP6)),$AP39*12,IF(BV$4=($AS6+$AP6),$AP39*VLOOKUP($AQ6,$E$79:$F$90,2,0),0))) -> 0 | BW39: =SUM(AT39:BV39) -> 0
B40: =B7 -> 2 | C40: =C7 -> 0 | D40: =IFERROR(AK7/D7/12,0) -> 0 | H40: =IF(H$4=$G7,$D40*(12-VLOOKUP($E7,$E$79:$F$90,2,0)),IF(AND(H$4>$G7,H$4<($G7+$D7)),$D40*12,IF(H$4=($G7+$D7),$D40*VLOOKUP($E7,$E$79:$F$90,2,0),0))) -> 0 | I40: =IF(I$4=$G7,$D40*(12-VLOOKUP($E7,$E$79:$F$90,2,0)),IF(AND(I$4>$G7,I$4<($G7+$D7)),$D40*12,IF(I$4=($G7+$D7),$D40*VLOOKUP($E7,$E$79:$F$90,2,0),0))) -> 0 | J40: =IF(J$4=$G7,$D40*(12-VLOOKUP($E7,$E$79:$F$90,2,0)),IF(AND(J$4>$G7,J$4<($G7+$D7)),$D40*12,IF(J$4=($G7+$D7),$D40*VLOOKUP($E7,$E$79:$F$90,2,0),0))) -> 0 | K40: =IF(K$4=$G7,$D40*(12-VLOOKUP($E7,$E$79:$F$90,2,0)),IF(AND(K$4>$G7,K$4<($G7+$D7)),$D40*12,IF(K$4=($G7+$D7),$D40*VLOOKUP($E7,$E$79:$F$90,2,0),0))) -> 0 | L40: =IF(L$4=$G7,$D40*(12-VLOOKUP($E7,$E$79:$F$90,2,0)),IF(AND(L$4>$G7,L$4<($G7+$D7)),$D40*12,IF(L$4=($G7+$D7),$D40*VLOOKUP($E7,$E$79:$F$90,2,0),0))) -> 0 | M40: =IF(M$4=$G7,$D40*(12-VLOOKUP($E7,$E$79:$F$90,2,0)),IF(AND(M$4>$G7,M$4<($G7+$D7)),$D40*12,IF(M$4=($G7+$D7),$D40*VLOOKUP($E7,$E$79:$F$90,2,0),0))) -> 0 | N40: =IF(N$4=$G7,$D40*(12-VLOOKUP($E7,$E$79:$F$90,2,0)),IF(AND(N$4>$G7,N$4<($G7+$D7)),$D40*12,IF(N$4=($G7+$D7),$D40*VLOOKUP($E7,$E$79:$F$90,2,0),0))) -> 0 | O40: =IF(O$4=$G7,$D40*(12-VLOOKUP($E7,$E$79:$F$90,2,0)),IF(AND(O$4>$G7,O$4<($G7+$D7)),$D40*12,IF(O$4=($G7+$D7),$D40*VLOOKUP($E7,$E$79:$F$90,2,0),0))) -> 0 | ... AJ40: =IF(AJ$4=$G7,$D40*(12-VLOOKUP($E7,$E$79:$F$90,2,0)),IF(AND(AJ$4>$G7,AJ$4<($G7+$D7)),$D40*12,IF(AJ$4=($G7+$D7),$D40*VLOOKUP($E7,$E$79:$F$90,2,0),0))) -> 0 | AK40: =SUM(H40:AJ40) -> 0 | AN40: =AN7 -> 2 | AO40: =AO7 -> 0 | AP40: =IFERROR(BW7/AP7/12,0) -> 0 | AT40: =IF(AT$4=$AS7,$AP40*(12-VLOOKUP($AQ7,$E$79:$F$90,2,0)),IF(AND(AT$4>$AS7,AT$4<($AS7+$AP7)),$AP40*12,IF(AT$4=($AS7+$AP7),$AP40*VLOOKUP($AQ7,$E$79:$F$90,2,0),0))) -> 0 | AU40: =IF(AU$4=$AS7,$AP40*(12-VLOOKUP($AQ7,$E$79:$F$90,2,0)),IF(AND(AU$4>$AS7,AU$4<($AS7+$AP7)),$AP40*12,IF(AU$4=($AS7+$AP7),$AP40*VLOOKUP($AQ7,$E$79:$F$90,2,0),0))) -> 0 | AV40: =IF(AV$4=$AS7,$AP40*(12-VLOOKUP($AQ7,$E$79:$F$90,2,0)),IF(AND(AV$4>$AS7,AV$4<($AS7+$AP7)),$AP40*12,IF(AV$4=($AS7+$AP7),$AP40*VLOOKUP($AQ7,$E$79:$F$90,2,0),0))) -> 0 | AW40: =IF(AW$4=$AS7,$AP40*(12-VLOOKUP($AQ7,$E$79:$F$90,2,0)),IF(AND(AW$4>$AS7,AW$4<($AS7+$AP7)),$AP40*12,IF(AW$4=($AS7+$AP7),$AP40*VLOOKUP($AQ7,$E$79:$F$90,2,0),0))) -> 0 | AX40: =IF(AX$4=$AS7,$AP40*(12-VLOOKUP($AQ7,$E$79:$F$90,2,0)),IF(AND(AX$4>$AS7,AX$4<($AS7+$AP7)),$AP40*12,IF(AX$4=($AS7+$AP7),$AP40*VLOOKUP($AQ7,$E$79:$F$90,2,0),0))) -> 0 | AY40: =IF(AY$4=$AS7,$AP40*(12-VLOOKUP($AQ7,$E$79:$F$90,2,0)),IF(AND(AY$4>$AS7,AY$4<($AS7+$AP7)),$AP40*12,IF(AY$4=($AS7+$AP7),$AP40*VLOOKUP($AQ7,$E$79:$F$90,2,0),0))) -> 0 | AZ40: =IF(AZ$4=$AS7,$AP40*(12-VLOOKUP($AQ7,$E$79:$F$90,2,0)),IF(AND(AZ$4>$AS7,AZ$4<($AS7+$AP7)),$AP40*12,IF(AZ$4=($AS7+$AP7),$AP40*VLOOKUP($AQ7,$E$79:$F$90,2,0),0))) -> 0 | BA40: =IF(BA$4=$AS7,$AP40*(12-VLOOKUP($AQ7,$E$79:$F$90,2,0)),IF(AND(BA$4>$AS7,BA$4<($AS7+$AP7)),$AP40*12,IF(BA$4=($AS7+$AP7),$AP40*VLOOKUP($AQ7,$E$79:$F$90,2,0),0))) -> 0 | ... BV40: =IF(BV$4=$AS7,$AP40*(12-VLOOKUP($AQ7,$E$79:$F$90,2,0)),IF(AND(BV$4>$AS7,BV$4<($AS7+$AP7)),$AP40*12,IF(BV$4=($AS7+$AP7),$AP40*VLOOKUP($AQ7,$E$79:$F$90,2,0),0))) -> 0 | BW40: =SUM(AT40:BV40) -> 0
B41: =B8 -> 3 | C41: =C8 -> 0 | D41: =IFERROR(AK8/D8/12,0) -> 0 | H41: =IF(H$4=$G8,$D41*(12-VLOOKUP($E8,$E$79:$F$90,2,0)),IF(AND(H$4>$G8,H$4<($G8+$D8)),$D41*12,IF(H$4=($G8+$D8),$D41*VLOOKUP($E8,$E$79:$F$90,2,0),0))) -> 0 | I41: =IF(I$4=$G8,$D41*(12-VLOOKUP($E8,$E$79:$F$90,2,0)),IF(AND(I$4>$G8,I$4<($G8+$D8)),$D41*12,IF(I$4=($G8+$D8),$D41*VLOOKUP($E8,$E$79:$F$90,2,0),0))) -> 0 | J41: =IF(J$4=$G8,$D41*(12-VLOOKUP($E8,$E$79:$F$90,2,0)),IF(AND(J$4>$G8,J$4<($G8+$D8)),$D41*12,IF(J$4=($G8+$D8),$D41*VLOOKUP($E8,$E$79:$F$90,2,0),0))) -> 0 | K41: =IF(K$4=$G8,$D41*(12-VLOOKUP($E8,$E$79:$F$90,2,0)),IF(AND(K$4>$G8,K$4<($G8+$D8)),$D41*12,IF(K$4=($G8+$D8),$D41*VLOOKUP($E8,$E$79:$F$90,2,0),0))) -> 0 | L41: =IF(L$4=$G8,$D41*(12-VLOOKUP($E8,$E$79:$F$90,2,0)),IF(AND(L$4>$G8,L$4<($G8+$D8)),$D41*12,IF(L$4=($G8+$D8),$D41*VLOOKUP($E8,$E$79:$F$90,2,0),0))) -> 0 | M41: =IF(M$4=$G8,$D41*(12-VLOOKUP($E8,$E$79:$F$90,2,0)),IF(AND(M$4>$G8,M$4<($G8+$D8)),$D41*12,IF(M$4=($G8+$D8),$D41*VLOOKUP($E8,$E$79:$F$90,2,0),0))) -> 0 | N41: =IF(N$4=$G8,$D41*(12-VLOOKUP($E8,$E$79:$F$90,2,0)),IF(AND(N$4>$G8,N$4<($G8+$D8)),$D41*12,IF(N$4=($G8+$D8),$D41*VLOOKUP($E8,$E$79:$F$90,2,0),0))) -> 0 | O41: =IF(O$4=$G8,$D41*(12-VLOOKUP($E8,$E$79:$F$90,2,0)),IF(AND(O$4>$G8,O$4<($G8+$D8)),$D41*12,IF(O$4=($G8+$D8),$D41*VLOOKUP($E8,$E$79:$F$90,2,0),0))) -> 0 | ... AJ41: =IF(AJ$4=$G8,$D41*(12-VLOOKUP($E8,$E$79:$F$90,2,0)),IF(AND(AJ$4>$G8,AJ$4<($G8+$D8)),$D41*12,IF(AJ$4=($G8+$D8),$D41*VLOOKUP($E8,$E$79:$F$90,2,0),0))) -> 0 | AK41: =SUM(H41:AJ41) -> 0 | AN41: =AN8 -> 3 | AO41: =AO8 -> 0 | AP41: =IFERROR(BW8/AP8/12,0) -> 0 | AT41: =IF(AT$4=$AS8,$AP41*(12-VLOOKUP($AQ8,$E$79:$F$90,2,0)),IF(AND(AT$4>$AS8,AT$4<($AS8+$AP8)),$AP41*12,IF(AT$4=($AS8+$AP8),$AP41*VLOOKUP($AQ8,$E$79:$F$90,2,0),0))) -> 0 | AU41: =IF(AU$4=$AS8,$AP41*(12-VLOOKUP($AQ8,$E$79:$F$90,2,0)),IF(AND(AU$4>$AS8,AU$4<($AS8+$AP8)),$AP41*12,IF(AU$4=($AS8+$AP8),$AP41*VLOOKUP($AQ8,$E$79:$F$90,2,0),0))) -> 0 | AV41: =IF(AV$4=$AS8,$AP41*(12-VLOOKUP($AQ8,$E$79:$F$90,2,0)),IF(AND(AV$4>$AS8,AV$4<($AS8+$AP8)),$AP41*12,IF(AV$4=($AS8+$AP8),$AP41*VLOOKUP($AQ8,$E$79:$F$90,2,0),0))) -> 0 | AW41: =IF(AW$4=$AS8,$AP41*(12-VLOOKUP($AQ8,$E$79:$F$90,2,0)),IF(AND(AW$4>$AS8,AW$4<($AS8+$AP8)),$AP41*12,IF(AW$4=($AS8+$AP8),$AP41*VLOOKUP($AQ8,$E$79:$F$90,2,0),0))) -> 0 | AX41: =IF(AX$4=$AS8,$AP41*(12-VLOOKUP($AQ8,$E$79:$F$90,2,0)),IF(AND(AX$4>$AS8,AX$4<($AS8+$AP8)),$AP41*12,IF(AX$4=($AS8+$AP8),$AP41*VLOOKUP($AQ8,$E$79:$F$90,2,0),0))) -> 0 | AY41: =IF(AY$4=$AS8,$AP41*(12-VLOOKUP($AQ8,$E$79:$F$90,2,0)),IF(AND(AY$4>$AS8,AY$4<($AS8+$AP8)),$AP41*12,IF(AY$4=($AS8+$AP8),$AP41*VLOOKUP($AQ8,$E$79:$F$90,2,0),0))) -> 0 | AZ41: =IF(AZ$4=$AS8,$AP41*(12-VLOOKUP($AQ8,$E$79:$F$90,2,0)),IF(AND(AZ$4>$AS8,AZ$4<($AS8+$AP8)),$AP41*12,IF(AZ$4=($AS8+$AP8),$AP41*VLOOKUP($AQ8,$E$79:$F$90,2,0),0))) -> 0 | BA41: =IF(BA$4=$AS8,$AP41*(12-VLOOKUP($AQ8,$E$79:$F$90,2,0)),IF(AND(BA$4>$AS8,BA$4<($AS8+$AP8)),$AP41*12,IF(BA$4=($AS8+$AP8),$AP41*VLOOKUP($AQ8,$E$79:$F$90,2,0),0))) -> 0 | ... BV41: =IF(BV$4=$AS8,$AP41*(12-VLOOKUP($AQ8,$E$79:$F$90,2,0)),IF(AND(BV$4>$AS8,BV$4<($AS8+$AP8)),$AP41*12,IF(BV$4=($AS8+$AP8),$AP41*VLOOKUP($AQ8,$E$79:$F$90,2,0),0))) -> 0 | BW41: =SUM(AT41:BV41) -> 0
